Workbook

Sheet Заявление_Виртуальная_АТС
C1: Данное письмо подлежит исполнению на фирменном бланке Вашей компании
C8: Исх.№ | D8: (укажите)
C9: Дата | D9: (укажите)
I10: Директору Департамента по развитию бизнес рынка Г-же Касымовой Д. Т.
C15: ЗАЯВЛЕНИЕ
C16: на подключение услуги «Виртуальная АТС»
C18: Настоящим, | H18: (далее - Компания) просит Вас подключить услугу «Виртуальная АТС»
C19: (Далее - Услуга) для совершения и приема звонков со следующими параметрами:
D21: Конфигурация Услуги | H21: (выберите из списка)
D22: Стоимость подключения | H22: =VLOOKUP(H$21,Sheet2!$B$2:$I$9,2,0) -> 0 | J22: тенге
D23: Ежемесячная плата за Услугу в месяц* | H23: =VLOOKUP(H$21,Sheet2!$B$2:$I$9,3,0)+H26*1000+H27*1000 -> 0 | J23: тенге
D24: - включено Виртуальных номеров | H24: =VLOOKUP(H$21,Sheet2!$B$2:$I$9,4,0) -> 0 | J24: шт
D25: - включено Пользователей (внут номеров)** | H25: =VLOOKUP(H$21,Sheet2!$B$2:$I$9,5,0) -> 0 | J25: чел
D26: Количество дополнительных Виртуальных номеров | H26: 0 | J26: шт
D27: Количество дополнительных Пользователей | H27: 0 | J27: чел
D28: *Абонентская плата по Услуге за месяц, в котором было подключение Услуги, начисляется Компанией пропорционально количеству дней, оставшихся до конца календарного месяца, включая день подключения, а затем 1-го числа каждого месяца в полном размере. Цены указаны в тенге с учетом НДС **Общее количество сессий предоставляется из расчета один Пользователь 2 сессии (единовременных звонка)
D30: Дополнительные услуги
D31: Модуль «Статистика», ежемесячно | H31: Не подключать | I31: =IF(H31="Подключить",4000,0) -> 0 | K31: тенге
D32: Модуль «Контроль качества», ежемесячно | H32: Не подключать | I32: =IF(H32="Подключить",4000,0) -> 0 | K32: тенге
D33: Модуль «Интеграция с CRM», ежемесячно | H33: Не подключать | I33: =IF(H33="Подключить",4000,0) -> 0 | K33: тенге
D34: Модуль «Заказ обратного звонка с сайта», ежемесячно | H34: Не подключать | I34: =IF(H34="Подключить",6000,0) -> 0 | K34: тенге
D35: Модуль «SIP регистрация», ежемесячно | H35: Не подключать | I35: =IF(H35="Подключить",4000,0) -> 0 | K35: тенге
D36: Модуль «Оценка качества обслуживания», ежемесячно | H36: Не подключать | I36: =IF(H36="Подключить",4000,0) -> 0 | K36: тенге
D37: Модуль «Номер в очереди», ежемесячно | H37: Не подключать | I37: =IF(H37="Подключить",4000,0) -> 0 | K37: тенге
D38: Модуль «Онлайн прослушивание и суфлирование», ежемесячно | H38: Не подключать | I38: =IF(H38="Подключить",4000,0) -> 0 | K38: тенге
D39: Модуль «Комнаты конференций», ежемесячно | H39: Не подключать | I39: =IF(H39="Подключить",4000,0) -> 0 | K39: тенге
D40: Модуль «Автообзвон», ежемесячно | H40: Не подключать | I40: =IF(H40="Подключить",4000,0) -> 0 | K40: тенге
D41: Модуль «Карусель номеров», ежемесячно | H41: Не подключать | I41: =IF(H41="Подключить",4000,0) -> 0 | K41: тенге
F43: Пакет «Эффективные продажи»
D44: Модуль «Уведомление о пропущенных звонках», ежемесячно | H44: Не подключать | I44: =IF(H44="Подключить",12000,0) -> 0 | K44: тенге
D45: Модуль «Виджет обратного звонка с сайта» , ежемесячно
D46: Модуль «Интеграция с CRM», ежемесячно
D47: Модуль «Статистика», ежемесячно
D48: Модуль «Карусель номеров», ежемесячно
F50: Пакет «Колл-центр»
D51: Модуль «Уведомление о номере в очереди», ежемесячно | H51: Не подключать | I51: =IF(H51="Подключить",10000,0) -> 0 | K51: тенге
D52: Модуль «Оценка качества обслуживания» , ежемесячно
D53: Модуль «Онлайн прослушивание и суфлирование», ежемесячно
D54: Модуль «Мониторинг очередей», ежемесячно
D55: Модуль «Статистика», ежемесячно
...

Sheet Sheet2
C1: Подключение | D1: АП | E1: virtual numbers | F1: extension
A2: (выберите из списка) | B2: (выберите из списка) | C2: 0 | D2: 0 | E2: 0 | F2: 0 | G2: 0 | H2: 0 | I2: 0
B3: Пакет 5 | C3: 0 | D3: 6000 | E3: 1 | F3: 5 | G3: 1000 | H3: 0
B4: Пакет 15 | C4: 0 | D4: 12000 | E4: 3 | F4: 15 | G4: 1000 | H4: 0
B5: Пакет 30 | C5: 0 | D5: 20000 | E5: 5 | F5: 30 | G5: 1000 | H5: 0
B6: Пакет 50 | C6: 0 | D6: 32000 | E6: 10 | F6: 50 | G6: 1000 | H6: 0
B7: Пакет 80 | C7: 0 | D7: 50000 | E7: 15 | F7: 80 | G7: 1000 | H7: 0
B8: Пакет 150 | C8: 0 | D8: 93000 | E8: 30 | F8: 150 | G8: 1000 | H8: 0
B9: Пакет 200 | C9: 0 | D9: 123000 | E9: 40 | F9: 200 | G9: 1000 | H9: 0
A11: Подключить | B11: Модуль «Инструменты для отделов продаж» | C11: При подключении допуслуги "Контроль качетсва", Абонент руководствуется инструкциями, указанными в личном кабинете. При этом, произведенная Абонентом запись разговора хранится не более 6 месяцев с даты записи. Абонент самостоятельно, используя настройки допуслуги осуществляет уведомление абонентов о производимой записи разговоров и несет за это ответственность в соответствии с действующим законодательством РК. При этом Оператор не несет ответственность за передачу/доступ третьих лиц к записям разговоров.
A12: Не подключать | B12: Модуль «Интеграция с CRM»
B13: Модуль «Аналитика»
B14: Модуль «Подключение физической АТС»
B15: Запись IVR на одном языке
B16: Модуль "SIP регистрация"
B17: Модуль «Оценка качества обслуживания»
B18: Модуль «Номер в очереди»
B19: Модуль «Онлайн прослушивание и суфлирование»
B20: Модуль «Комнаты конференций»
B21: Модуль «Автообзвон»
B22: Модуль «Речевая аналитика»
B23: Модуль «Карусель номеров»
B34: Модуль "FMC" | C34: К дополнительной услуге "FMC" подключаются только SIM карты корпоративной группы Кселл. При этом, списание Абонентской Платы происходит согласно условиям тарифного плана на SIM карте Абонента. Для осуществления звонков по короткой нумерации внутри домена Виртуальной АТС, необходимо использовать префикс ** перед номером, за звонки, совершенные иным способ, Оператор ответственности не несет и не гарантирует корректность тарификации по ним. Дополнительная услуга FMC несовместима с услугой FreePhone (Бесплатный вызов) в связи с техническими ограничениями. С условиями оказания дополнительной услуги ознакомлены и согласны, включая, но, не ограничиваясь: услуга доступна при наличии на балансе средств, достаточных для оплаты услуг связи (при авансовом порядке расчетов) и в пределах кредитного лимита (при кредитном порядке расчетов).
C37: АП | D37: MIN | E37: CUG | F37: ONNET | G37: OFFNET | H37: PSTN
A38: (выберите из списка) | B38: (выберите из списка) | C38: 0 | D38: 0 | E38: 0 | F38: 0 | G38: 0 | H38: 0
B39: Виртуальный 5 | C39: 5000 | D39: 555 | E39: 0 | F39: 11 | G39: 11 | H39: 17 | I39: *В абонентскую плату включена стоимость ежемесячного пакета минут для звонков на номера всех сотовых операторов по Казахстану, кроме звонков внутри виртуальной АТС и внутри корпоративной группы. При подключении любого из тарифных планов абонентская плата списывается пропорционально количеству дней, оставшихся до конца календарного месяца, включая день подключения и затем каждое 1-ое число месяца в полном размере. При списании абонентской платы включенный бонусный пакет минут по тарифным планам будет предоставлен в полном объеме. Тарифы указаны в тенге с учетом НДС ** минуты в пакете действуют в течение календарного месяца и на следующий месяц не переносятся. После исчерпания пакета минут в учетном месяце исходящие звонки на указанные направления по Казахстану тарифицируются согласно условиям Тарифного плана.
B40: Виртуальный 10 | C40: 10000 | D40: 1250 | E40: 0 | F40: 11 | G40: 11 | H40: 17 | I40: *В абонентскую плату включена стоимость ежемесячного пакета минут для звонков на номера всех сотовых операторов по Казахстану, кроме звонков внутри виртуальной АТС и внутри корпоративной группы. При подключении любого из тарифных планов абонентская плата списывается пропорционально количеству дней, оставшихся до конца календарного месяца, включая день подключения и затем каждое 1-ое число месяца в полном размере. При списании абонентской платы включенный бонусный пакет минут по тарифным планам будет предоставлен в полном объеме. Тарифы указаны в тенге с учетом НДС ** минуты в пакете действуют в течение календарного месяца и на следующий месяц не переносятся. После исчерпания пакета минут в учетном месяце исходящие звонки на указанные направления по Казахстану тарифицируются согласно условиям Тарифного плана.
B41: Виртуальный 30 | C41: 30000 | D41: 4000 | E41: 0 | F41: 11 | G41: 11 | H41: 17 | I41: *В абонентскую плату включена стоимость ежемесячного пакета минут для звонков на номера всех сотовых операторов по Казахстану, кроме звонков внутри виртуальной АТС и внутри корпоративной группы. При подключении любого из тарифных планов абонентская плата списывается пропорционально количеству дней, оставшихся до конца календарного месяца, включая день подключения и затем каждое 1-ое число месяца в полном размере. При списании абонентской платы включенный бонусный пакет минут по тарифным планам будет предоставлен в полном объеме. Тарифы указаны в тенге с учетом НДС ** минуты в пакете действуют в течение календарного месяца и на следующий месяц не переносятся. После исчерпания пакета минут в учетном месяце исходящие звонки на указанные направления по Казахстану тарифицируются согласно условиям Тарифного плана.
B42: Виртуальный 50 | C42: 50000 | D42: 7000 | E42: 0 | F42: 11 | G42: 11 | H42: 17 | I42: *В абонентскую плату включена стоимость ежемесячного пакета минут для звонков на номера всех сотовых операторов по Казахстану, кроме звонков внутри виртуальной АТС и внутри корпоративной группы. При подключении любого из тарифных планов абонентская плата списывается пропорционально количеству дней, оставшихся до конца календарного месяца, включая день подключения и затем каждое 1-ое число месяца в полном размере. При списании абонентской платы включенный бонусный пакет минут по тарифным планам будет предоставлен в полном объеме. Тарифы указаны в тенге с учетом НДС ** минуты в пакете действуют в течение календарного месяца и на следующий месяц не переносятся. После исчерпания пакета минут в учетном месяце исходящие звонки на указанные направления по Казахстану тарифицируются согласно условиям Тарифного плана.
B43: Виртуальный 150 | C43: 150000 | D43: 20000 | E43: 0 | F43: 10.5 | G43: 10.5 | H43: 17 | I43: *В абонентскую плату включена стоимость ежемесячного пакета минут для звонков на номера всех сотовых операторов по Казахстану, кроме звонков внутри виртуальной АТС и внутри корпоративной группы. При подключении любого из тарифных планов абонентская плата списывается пропорционально количеству дней, оставшихся до конца календарного месяца, включая день подключения и затем каждое 1-ое число месяца в полном размере. При списании абонентской платы включенный бонусный пакет минут по тарифным планам будет предоставлен в полном объеме. Тарифы указаны в тенге с учетом НДС ** минуты в пакете действуют в течение календарного месяца и на следующий месяц не переносятся. После исчерпания пакета минут в учетном месяце исходящие звонки на указанные направления по Казахстану тарифицируются согласно условиям Тарифного плана.
B44: Виртуальный 200 | C44: 200000 | D44: 28571 | E44: 0 | F44: 10.5 | G44: 10.5 | H44: 17 | I44: *В абонентскую плату включена стоимость ежемесячного пакета минут для звонков на номера всех сотовых операторов по Казахстану, кроме звонков внутри виртуальной АТС и внутри корпоративной группы. При подключении любого из тарифных планов абонентская плата списывается пропорционально количеству дней, оставшихся до конца календарного месяца, включая день подключения и затем каждое 1-ое число месяца в полном размере. При списании абонентской платы включенный бонусный пакет минут по тарифным планам будет предоставлен в полном объеме. Тарифы указаны в тенге с учетом НДС ** минуты в пакете действуют в течение календарного месяца и на следующий месяц не переносятся. После исчерпания пакета минут в учетном месяце исходящие звонки на указанные направления по Казахстану тарифицируются согласно условиям Тарифного плана.
B45: Виртуальный 600 | C45: 600000 | D45: 85714 | E45: 0 | F45: 10 | G45: 10 | H45: 17 | I45: *В абонентскую плату включена стоимость ежемесячного пакета минут для звонков на номера всех сотовых операторов по Казахстану, кроме звонков внутри виртуальной АТС и внутри корпоративной группы. При подключении любого из тарифных планов абонентская плата списывается пропорционально количеству дней, оставшихся до конца календарного месяца, включая день подключения и затем каждое 1-ое число месяца в полном размере. При списании абонентской платы включенный бонусный пакет минут по тарифным планам будет предоставлен в полном объеме. Тарифы указаны в тенге с учетом НДС ** минуты в пакете действуют в течение календарного месяца и на следующий месяц не переносятся. После исчерпания пакета минут в учетном месяце исходящие звонки на указанные направления по Казахстану тарифицируются согласно условиям Тарифного плана.
B46: Виртуальный 700 | C46: 700000 | D46: 100000 | E46: 0 | F46: 9 | G46: 9 | H46: 17 | I46: *В абонентскую плату включена стоимость ежемесячного пакета минут для звонков на номера всех сотовых операторов по Казахстану, кроме звонков внутри виртуальной АТС и внутри корпоративной группы. При подключении любого из тарифных планов абонентская плата списывается пропорционально количеству дней, оставшихся до конца календарного месяца, включая день подключения и затем каждое 1-ое число месяца в полном размере. При списании абонентской платы включенный бонусный пакет минут по тарифным планам будет предоставлен в полном объеме. Тарифы указаны в тенге с учетом НДС ** минуты в пакете действуют в течение календарного месяца и на следующий месяц не переносятся. После исчерпания пакета минут в учетном месяце исходящие звонки на указанные направления по Казахстану тарифицируются согласно условиям Тарифного плана.
B47: Виртуальный 1 MLN | C47: 1000000 | D47: 142857 | E47: 0 | F47: 9 | G47: 9 | H47: 17 | I47: *В абонентскую плату включена стоимость ежемесячного пакета минут для звонков на номера всех сотовых операторов по Казахстану, кроме звонков внутри виртуальной АТС и внутри корпоративной группы. При подключении любого из тарифных планов абонентская плата списывается пропорционально количеству дней, оставшихся до конца календарного месяца, включая день подключения и затем каждое 1-ое число месяца в полном размере. При списании абонентской платы включенный бонусный пакет минут по тарифным планам будет предоставлен в полном объеме. Тарифы указаны в тенге с учетом НДС ** минуты в пакете действуют в течение календарного месяца и на следующий месяц не переносятся. После исчерпания пакета минут в учетном месяце исходящие звонки на указанные направления по Казахстану тарифицируются согласно условиям Тарифного плана.
A49: (выберите из списка)
A50: Открыть
A51: Закрыть
