Workbook

Sheet Заявление_Виртуальная_АТС
C1: Осы хат Сіздің компанияңыздың фирмалық бланкіcінде орындалуы тиіс
C8: Шығ.№ | D8: (көрсетіңіз)
C9: Күні | D9: (көрсетіңіз)
I10: Бизнес нарықты дамыту департаментінің директоры Д.Т.Касымова ханымға
C15: «Виртуалды АТС» қызметін қосуға
C16: ӨТІНІШ
C18: Осымен, | H18: (бұдан әрі - Компания) Сізден мынадай параметрлермен қоңыраулар
D19: жасау және қабылдау үшін «Виртуалды АТС» қызметін (бұдан әрі - Қызмет) қосуды сұрайды:
D21: Қызмет Конфигурациясы | H21: (тізімнен таңдаңыз)
D22: Қосу құны | H22: =VLOOKUP(H$21,Sheet2!$B$2:$I$9,2,0) -> 0 | J22: теңге
D23: Қызмет үшін ай сайынғы төлем, айына* | H23: =VLOOKUP(H$21,Sheet2!$B$2:$I$9,3,0)+H26*1000+H27*1000 -> 0 | J23: теңге
D24: - Виртуалды нөмір қосылған | H24: =VLOOKUP(H$21,Sheet2!$B$2:$I$9,4,0) -> 0 | J24: дана
D25: - Пайдаланушы (ішкі нөмір) қосылған** | H25: =VLOOKUP(H$21,Sheet2!$B$2:$I$9,5,0) -> 0 | J25: адам
D26: қосымша Виртуалды нөмірлердің саны | J26: дана
D27: Қосымша Пайдаланушылар саны | J27: адам
D28: *Қызмет қосылған айдағы Қызметтің абоненттік төлемін Компания, қосу күнін қоса алғанда, күнтізбелік айдың соңына дейін қалған күндер санына барабар мөлшерде, содан соң әрбір айдың 1-ші күнінде толық мөлшерде есептейді. Бағалар теңгемен, ҚҚС есебімен көрсетілген **Сессиялардың жалпы саны бір Пайдаланушыға 2 сессия (қатарласа жүретін қоңырау) есебінен беріледі
D30: Қосымша қызметтер
D31: «Статистика» модулі, ай сайын | H31: Қосылмау | I31: =IF(H31="Қосылу",4000,0) -> 0 | K31: теңге
D32: «Сапаны бақылау» модулі, ай сайын | H32: Қосылмау | I32: =IF(H32="Қосылу",4000,0) -> 0 | K32: теңге
D33: «CRM-мен интеграция» модулі, ай сайын | H33: Қосылмау | I33: =IF(H33="Қосылу",4000,0) -> 0 | K33: теңге
D34: «Сайттан кері қоңырауға тапсырыс беру» модулі, ай сайын | H34: Қосылмау | I34: =IF(H34="Қосылу",6000,0) -> 0 | K34: теңге
D35: «SIP-тіркеу» модулі, ай сайын | H35: Қосылмау | I35: =IF(H35="Қосылу",4000,0) -> 0 | K35: теңге
D36: «Қызмет көрсету сапасын бағалау» модулі, ай сайын | H36: Қосылмау | I36: =IF(H36="Қосылу",4000,0) -> 0 | K36: теңге
D37: «Кезектегi нөмір» модулі, ай сайын | H37: Қосылмау | I37: =IF(H37="Қосылу",4000,0) -> 0 | K37: теңге
D38: Модуль «Онлайн тыңдау және Суфлирлеу» модулі, ай сайын | H38: Қосылмау | I38: =IF(H38="Қосылу",4000,0) -> 0 | K38: теңге
D39: «Конференция бөлмелері» модулі, ай сайын | H39: Қосылмау | I39: =IF(H39="Қосылу",4000,0) -> 0 | K39: теңге
D40: «Авто қоңырау шалу » модулі, ай сайын | H40: Қосылмау | I40: =IF(H40="Қосылу",4000,0) -> 0 | K40: теңге
D41: =IF(#REF!="Подключить",Sheet2!C22," ")&IF(H32="Подключить",Sheet2!C11," ") -> #REF!
G43: Речевая аналитика
D44: "Сөйлеуді талдау" модулі сай сайын* | H44: Қосылмау | I44: =IF(H44="Қосылу",4000,0) -> 0 | K44: теңге
D45: "Сөйлеуді талдауды" падаланушылар үшін ай сайынғы төлем"* | I45: =IF(H44="Қосылу",H25*1000+H27*1000,"0") -> 0 | K45: теңге
D46: * Модульді қосқан кезде тегін пайдаланушыларды қоса алғанда, бұрын қосылған барлық пайдаланушылар ақылы негізге көшеді
D49: Тарифтік жоспар | H49: (тізімнен таңдаңыз)
D50: Ай сайынғы абоненттік төлем* | H50: =VLOOKUP(H49,Sheet2!$B$26:$H$35,2,0) -> 0 | J50: теңге
D51: Қазақстан бойынша барлық мобильді операторлардың нөмірлеріне қоңырау шалуға арналған ай сайынғы минуттар топтамасы** | H51: =VLOOKUP(H49,Sheet2!$B$26:$H$35,3,0) -> 0 | J51: минут
D52: Минуттар топтамасынан тыс шығыс қоңыраулары: | H52: Құны, теңге, ҚҚС-пен | J52: Тарифтеу қадамы
D53: Виртуалды АТС ішінде (ішкі нөмірлерге) және корпоративтік топ ішінде, минутына | H53: =VLOOKUP(H49,Sheet2!$B$26:$H$35,4,0) -> 0 | J53: 1 сек
D54: Kcell, Activ желісі ішінде, минутына | H54: =VLOOKUP(H49,Sheet2!$B$26:$H$35,5,0) -> 0 | J54: 1 сек
D55: ҚР басқа ұялы операторларына, минутына | H55: =VLOOKUP(H49,Sheet2!$B$26:$H$94,6,0) -> 0 | J55: 1 сек
D56: ҚР қалалық нөмірлеріне, минутына | H56: =VLOOKUP(H49,Sheet2!$B$26:$H$35,7,0) -> 0 | J56: 1 сек
...

Sheet Лист1

Sheet Sheet2
C1: Подключение | D1: АП | E1: virtual numbers | F1: extension
A2: (тізімнен таңдаңыз) | B2: (тізімнен таңдаңыз) | C2: 0 | D2: 0 | E2: 0 | F2: 0 | G2: 0 | H2: 0 | I2: 0
B3: Пакет 5 | C3: 0 | D3: 6000 | E3: 1 | F3: 5 | G3: 1000 | H3: 0
B4: Пакет 15 | C4: 0 | D4: 12000 | E4: 3 | F4: 15 | G4: 1000 | H4: 0
B5: Пакет 30 | C5: 0 | D5: 20000 | E5: 5 | F5: 30 | G5: 1000 | H5: 0
B6: Пакет 50 | C6: 0 | D6: 32000 | E6: 10 | F6: 50 | G6: 1000 | H6: 0
B7: Пакет 80 | C7: 0 | D7: 50000 | E7: 15 | F7: 80 | G7: 1000 | H7: 0
B8: Пакет 150 | C8: 0 | D8: 93000 | E8: 30 | F8: 150 | G8: 1000 | H8: 0
B9: Пакет 200 | C9: 0 | D9: 123000 | E9: 40 | F9: 200 | G9: 1000 | H9: 0
A11: Қосылу | B11: Модуль «Инструменты для отделов продаж» | C11: При подключении допуслуги "Контроль качетсва", Абонент руководствуется инструкциями, указанными в личном кабинете. При этом, произведенная Абонентом запись разговора хранится не более 6 месяцев с даты записи. Абонент самостоятельно, используя настройки допуслуги осуществляет уведомление абонентов о производимой записи разговоров и несет за это ответственность в соответствии с действующим законодательством РК. При этом Оператор не несет ответственность за передачу/доступ третьих лиц к записям разговоров.
A12: Қосылмау | B12: Модуль «Интеграция с CRM»
B13: Модуль «Аналитика»
B14: Модуль «Подключение физической АТС»
B15: Запись IVR на одном языке
B16: Модуль "SIP регистрация"
B17: Модуль «Оценка качества обслуживания»
B18: Модуль «Номер в очереди»
B19: Модуль «Онлайн прослушивание и суфлирование»
B20: Модуль «Комнаты конференций»
B21: Модуль «Автообзвон»
B22: Модуль "FMC" | C22: К дополнительной услуге "FMC" подключаются только SIM карты корпоративной группы Кселл. При этом, списание Абонентской Платы происходит согласно условиям тарифного плана на SIM карте Абонента. Для осуществления звонков по короткой нумерации внутри домена Виртуальной АТС, необходимо использовать префикс ** перед номером, за звонки, совершенные иным способ, Оператор ответственности не несет и не гарантирует корректность тарификации по ним. Дополнительная услуга FMC несовместима с услугой FreePhone (Бесплатный вызов) в связи с техническими ограничениями. С условиями оказания дополнительной услуги ознакомлены и согласны, включая, но, не ограничиваясь: услуга доступна при наличии на балансе средств, достаточных для оплаты услуг связи (при авансовом порядке расчетов) и в пределах кредитного лимита (при кредитном порядке расчетов).
C25: АП | D25: MIN | E25: CUG | F25: ONNET | G25: OFFNET | H25: PSTN
A26: (тізімнен таңдаңыз) | B26: (тізімнен таңдаңыз) | C26: 0 | D26: 0 | E26: 0 | F26: 0 | G26: 0 | H26: 0
B27: Виртуальный 5 | C27: 5000 | D27: 555 | E27: 0 | F27: 11 | G27: 11 | H27: 17 | I27: *В абонентскую плату включена стоимость ежемесячного пакета минут для звонков на номера всех сотовых операторов по Казахстану, кроме звонков внутри виртуальной АТС и внутри корпоративной группы. При подключении любого из тарифных планов абонентская плата списывается пропорционально количеству дней, оставшихся до конца календарного месяца, включая день подключения и затем каждое 1-ое число месяца в полном размере. При списании абонентской платы включенный бонусный пакет минут по тарифным планам будет предоставлен в полном объеме. Тарифы указаны в тенге с учетом НДС ** минуты в пакете действуют в течение календарного месяца и на следующий месяц не переносятся. После исчерпания пакета минут в учетном месяце исходящие звонки на указанные направления по Казахстану тарифицируются согласно условиям Тарифного плана.
B28: Виртуальный 10 | C28: 10000 | D28: 1250 | E28: 0 | F28: 11 | G28: 11 | H28: 17 | I28: *В абонентскую плату включена стоимость ежемесячного пакета минут для звонков на номера всех сотовых операторов по Казахстану, кроме звонков внутри виртуальной АТС и внутри корпоративной группы. При подключении любого из тарифных планов абонентская плата списывается пропорционально количеству дней, оставшихся до конца календарного месяца, включая день подключения и затем каждое 1-ое число месяца в полном размере. При списании абонентской платы включенный бонусный пакет минут по тарифным планам будет предоставлен в полном объеме. Тарифы указаны в тенге с учетом НДС ** минуты в пакете действуют в течение календарного месяца и на следующий месяц не переносятся. После исчерпания пакета минут в учетном месяце исходящие звонки на указанные направления по Казахстану тарифицируются согласно условиям Тарифного плана.
B29: Виртуальный 30 | C29: 30000 | D29: 4000 | E29: 0 | F29: 11 | G29: 11 | H29: 17 | I29: *В абонентскую плату включена стоимость ежемесячного пакета минут для звонков на номера всех сотовых операторов по Казахстану, кроме звонков внутри виртуальной АТС и внутри корпоративной группы. При подключении любого из тарифных планов абонентская плата списывается пропорционально количеству дней, оставшихся до конца календарного месяца, включая день подключения и затем каждое 1-ое число месяца в полном размере. При списании абонентской платы включенный бонусный пакет минут по тарифным планам будет предоставлен в полном объеме. Тарифы указаны в тенге с учетом НДС ** минуты в пакете действуют в течение календарного месяца и на следующий месяц не переносятся. После исчерпания пакета минут в учетном месяце исходящие звонки на указанные направления по Казахстану тарифицируются согласно условиям Тарифного плана.
B30: Виртуальный 50 | C30: 50000 | D30: 7000 | E30: 0 | F30: 11 | G30: 11 | H30: 17 | I30: *В абонентскую плату включена стоимость ежемесячного пакета минут для звонков на номера всех сотовых операторов по Казахстану, кроме звонков внутри виртуальной АТС и внутри корпоративной группы. При подключении любого из тарифных планов абонентская плата списывается пропорционально количеству дней, оставшихся до конца календарного месяца, включая день подключения и затем каждое 1-ое число месяца в полном размере. При списании абонентской платы включенный бонусный пакет минут по тарифным планам будет предоставлен в полном объеме. Тарифы указаны в тенге с учетом НДС ** минуты в пакете действуют в течение календарного месяца и на следующий месяц не переносятся. После исчерпания пакета минут в учетном месяце исходящие звонки на указанные направления по Казахстану тарифицируются согласно условиям Тарифного плана.
B31: Виртуальный 150 | C31: 150000 | D31: 20000 | E31: 0 | F31: 10.5 | G31: 10.5 | H31: 17 | I31: *В абонентскую плату включена стоимость ежемесячного пакета минут для звонков на номера всех сотовых операторов по Казахстану, кроме звонков внутри виртуальной АТС и внутри корпоративной группы. При подключении любого из тарифных планов абонентская плата списывается пропорционально количеству дней, оставшихся до конца календарного месяца, включая день подключения и затем каждое 1-ое число месяца в полном размере. При списании абонентской платы включенный бонусный пакет минут по тарифным планам будет предоставлен в полном объеме. Тарифы указаны в тенге с учетом НДС ** минуты в пакете действуют в течение календарного месяца и на следующий месяц не переносятся. После исчерпания пакета минут в учетном месяце исходящие звонки на указанные направления по Казахстану тарифицируются согласно условиям Тарифного плана.
B32: Виртуальный 200 | C32: 200000 | D32: 28571 | E32: 0 | F32: 10.5 | G32: 10.5 | H32: 17 | I32: *В абонентскую плату включена стоимость ежемесячного пакета минут для звонков на номера всех сотовых операторов по Казахстану, кроме звонков внутри виртуальной АТС и внутри корпоративной группы. При подключении любого из тарифных планов абонентская плата списывается пропорционально количеству дней, оставшихся до конца календарного месяца, включая день подключения и затем каждое 1-ое число месяца в полном размере. При списании абонентской платы включенный бонусный пакет минут по тарифным планам будет предоставлен в полном объеме. Тарифы указаны в тенге с учетом НДС ** минуты в пакете действуют в течение календарного месяца и на следующий месяц не переносятся. После исчерпания пакета минут в учетном месяце исходящие звонки на указанные направления по Казахстану тарифицируются согласно условиям Тарифного плана.
B33: Виртуальный 600 | C33: 600000 | D33: 85714 | E33: 0 | F33: 10 | G33: 10 | H33: 17 | I33: *В абонентскую плату включена стоимость ежемесячного пакета минут для звонков на номера всех сотовых операторов по Казахстану, кроме звонков внутри виртуальной АТС и внутри корпоративной группы. При подключении любого из тарифных планов абонентская плата списывается пропорционально количеству дней, оставшихся до конца календарного месяца, включая день подключения и затем каждое 1-ое число месяца в полном размере. При списании абонентской платы включенный бонусный пакет минут по тарифным планам будет предоставлен в полном объеме. Тарифы указаны в тенге с учетом НДС ** минуты в пакете действуют в течение календарного месяца и на следующий месяц не переносятся. После исчерпания пакета минут в учетном месяце исходящие звонки на указанные направления по Казахстану тарифицируются согласно условиям Тарифного плана.
B34: Виртуальный 700 | C34: 700000 | D34: 100000 | E34: 0 | F34: 9 | G34: 9 | H34: 17 | I34: *В абонентскую плату включена стоимость ежемесячного пакета минут для звонков на номера всех сотовых операторов по Казахстану, кроме звонков внутри виртуальной АТС и внутри корпоративной группы. При подключении любого из тарифных планов абонентская плата списывается пропорционально количеству дней, оставшихся до конца календарного месяца, включая день подключения и затем каждое 1-ое число месяца в полном размере. При списании абонентской платы включенный бонусный пакет минут по тарифным планам будет предоставлен в полном объеме. Тарифы указаны в тенге с учетом НДС ** минуты в пакете действуют в течение календарного месяца и на следующий месяц не переносятся. После исчерпания пакета минут в учетном месяце исходящие звонки на указанные направления по Казахстану тарифицируются согласно условиям Тарифного плана.
B35: Виртуальный 1 MLN | C35: 1000000 | D35: 142857 | E35: 0 | F35: 9 | G35: 9 | H35: 17 | I35: *В абонентскую плату включена стоимость ежемесячного пакета минут для звонков на номера всех сотовых операторов по Казахстану, кроме звонков внутри виртуальной АТС и внутри корпоративной группы. При подключении любого из тарифных планов абонентская плата списывается пропорционально количеству дней, оставшихся до конца календарного месяца, включая день подключения и затем каждое 1-ое число месяца в полном размере. При списании абонентской платы включенный бонусный пакет минут по тарифным планам будет предоставлен в полном объеме. Тарифы указаны в тенге с учетом НДС ** минуты в пакете действуют в течение календарного месяца и на следующий месяц не переносятся. После исчерпания пакета минут в учетном месяце исходящие звонки на указанные направления по Казахстану тарифицируются согласно условиям Тарифного плана.
A37: (тізімнен таңдаңыз)
A38: Открыть
A39: Закрыть
